I'm sorry, but an uncaught exception occurred.

While running game code:
  File "game/script.rpy", line 145, in script call
    call episode1 from _call_episode1
  File "game/episode 1.rpy", line 735, in script
    if scene5Wrong == True:
  File "game/episode 1.rpy", line 735, in <module>
    if scene5Wrong == True:
       ^^^^^^^^^^^         
NameError: name 'scene5Wrong' is not defined

-- Full Traceback ------------------------------------------------------------

Traceback (most recent call last):
  File "game/script.rpy", line 145, in script call
    call episode1 from _call_episode1
  File "game/episode 1.rpy", line 735, in script
    if scene5Wrong == True:
  File "renpy/ast.py", line 2079, in execute
    if renpy.python.py_eval(condition):
       ~~~~~~~~~~~~~~~~~~~~^^^^^^^^^^^ 
  File "renpy/python.py", line 1292, in py_eval
    return py_eval_bytecode(code, globals, locals)
           ~~~~~~~~~~~~~~~~^^^^^^^^^^^^^^^^^^^^^^^
  File "renpy/python.py", line 1285, in py_eval_bytecode
    return eval(bytecode, globals, locals)
           ~~~~^^^^^^^^^^^^^^^^^^^^^^^^^^^
  File "game/episode 1.rpy", line 735, in <module>
    if scene5Wrong == True:
       ^^^^^^^^^^^         
NameError: name 'scene5Wrong' is not defined

Windows-11-10.0.22621-SP0 AMD64
Ren'Py 8.4.1.25072401
Codebound 1.0
Thu Oct 30 06:22:31 2025
